<?xml version="1.0" ?>
<sdf version="1.7">
  <model name="trash_bot">
    <static>false</static>
    
    <!-- Base Link -->
    <link name="base_link">
      <pose>0 0 0.0325 0 0 0</pose> <!-- Raised by wheel radius -->
      
      <inertial>
        <pose>0 0 0.2 0 0 0</pose> <!-- Center of mass at half height -->
        <mass>5.0</mass>
        <inertia>
          <ixx>0.080166667</ixx>
          <ixy>0</ixy>
          <ixz>0</ixz>
          <iyy>0.080166667</iyy>
          <iyz>0</iyz>
          <izz>0.027</izz>
        </inertia>
      </inertial>

      <visual name="base_visual">
        <pose>0 0 0.2 0 0 0</pose>
        <geometry>
          <box>
            <size>0.18 0.18 0.40</size>
          </box>
        </geometry>
        <material>
          <ambient>0.2 0.2 0.8 1</ambient>
          <diffuse>0.2 0.2 0.8 1</diffuse>
        </material>
      </visual>

      <collision name="base_collision">
        <pose>0 0 0.2 0 0 0</pose>
        <geometry>
          <box>
            <size>0.18 0.18 0.40</size>
          </box>
        </geometry>
      </collision>

      <!-- Caster Wheel (Front) -->
      <visual name="front_caster_visual">
        <pose>0.07 0 -0.0175 0 0 0</pose>
        <geometry>
          <sphere>
            <radius>0.015</radius>
          </sphere>
        </geometry>
        <material>
          <ambient>0.1 0.1 0.1 1</ambient>
          <diffuse>0.1 0.1 0.1 1</diffuse>
        </material>
      </visual>

      <collision name="front_caster_collision">
        <pose>0.07 0 -0.0175 0 0 0</pose>
        <geometry>
          <sphere>
            <radius>0.015</radius>
          </sphere>
        </geometry>
        <surface>
          <friction>
            <ode>
              <mu>0.01</mu>
              <mu2>0.01</mu2>
            </ode>
          </friction>
        </surface>
      </collision>

      <!-- Caster Wheel (Back) -->
      <visual name="back_caster_visual">
        <pose>-0.07 0 -0.0175 0 0 0</pose>
        <geometry>
          <sphere>
            <radius>0.015</radius>
          </sphere>
        </geometry>
        <material>
          <ambient>0.1 0.1 0.1 1</ambient>
          <diffuse>0.1 0.1 0.1 1</diffuse>
        </material>
      </visual>

      <collision name="back_caster_collision">
        <pose>-0.07 0 -0.0175 0 0 0</pose>
        <geometry>
          <sphere>
            <radius>0.015</radius>
          </sphere>
        </geometry>
        <surface>
          <friction>
            <ode>
              <mu>0.01</mu>
              <mu2>0.01</mu2>
            </ode>
          </friction>
        </surface>
      </collision>
    </link>

    <!-- Left Wheel -->
    <link name="left_wheel">
      <pose>0 0.105 0.0325 -1.57079632679 0 0</pose>
      <inertial>
        <mass>0.15</mass>
        <inertia>
          <ixx>0.0000474375</ixx>
          <ixy>0</ixy>
          <ixz>0</ixz>
          <iyy>0.0000474375</iyy>
          <iyz>0</iyz>
          <izz>0.00007921875</izz>
        </inertia>
      </inertial>
      <visual name="visual">
        <geometry>
          <cylinder>
            <radius>0.0325</radius>
            <length>0.025</length>
          </cylinder>
        </geometry>
        <material>
          <ambient>0.1 0.1 0.1 1</ambient>
          <diffuse>0.1 0.1 0.1 1</diffuse>
        </material>
      </visual>
      <collision name="collision">
        <geometry>
          <cylinder>
            <radius>0.0325</radius>
            <length>0.025</length>
          </cylinder>
        </geometry>
      </collision>
    </link>

    <!-- Right Wheel -->
    <link name="right_wheel">
      <pose>0 -0.105 0.0325 -1.57079632679 0 0</pose>
      <inertial>
        <mass>0.15</mass>
        <inertia>
          <ixx>0.0000474375</ixx>
          <ixy>0</ixy>
          <ixz>0</ixz>
          <iyy>0.0000474375</iyy>
          <iyz>0</iyz>
          <izz>0.00007921875</izz>
        </inertia>
      </inertial>
      <visual name="visual">
        <geometry>
          <cylinder>
            <radius>0.0325</radius>
            <length>0.025</length>
          </cylinder>
        </geometry>
        <material>
          <ambient>0.1 0.1 0.1 1</ambient>
          <diffuse>0.1 0.1 0.1 1</diffuse>
        </material>
      </visual>
      <collision name="collision">
        <geometry>
          <cylinder>
            <radius>0.0325</radius>
            <length>0.025</length>
          </cylinder>
        </geometry>
      </collision>
    </link>

    <!-- Joints -->
    <joint name="left_wheel_joint" type="revolute">
      <parent>base_link</parent>
      <child>left_wheel</child>
      <axis>
        <xyz>0 0 1</xyz>
        <limit>
          <lower>-1e16</lower>
          <upper>1e16</upper>
        </limit>
      </axis>
    </joint>

    <joint name="right_wheel_joint" type="revolute">
      <parent>base_link</parent>
      <child>right_wheel</child>
      <axis>
        <xyz>0 0 1</xyz>
        <limit>
          <lower>-1e16</lower>
          <upper>1e16</upper>
        </limit>
      </axis>
    </joint>

    <!-- Lidar Sensor -->
    <link name="laser_frame">
      <pose>0 0 0.45 0 0 0</pose>
      <inertial>
        <mass>0.1</mass>
        <inertia>
          <ixx>0.0001</ixx>
          <ixy>0</ixy>
          <ixz>0</ixz>
          <iyy>0.0001</iyy>
          <iyz>0</iyz>
          <izz>0.0001</izz>
        </inertia>
      </inertial>
      <visual name="visual">
        <geometry>
          <cylinder>
            <radius>0.035</radius>
            <length>0.04</length>
          </cylinder>
        </geometry>
        <material>
          <ambient>0.8 0.2 0.2 1</ambient>
          <diffuse>0.8 0.2 0.2 1</diffuse>
        </material>
      </visual>
      <sensor name="lidar" type="ray">
        <pose>0 0 0 0 0 0</pose>
        <always_on>true</always_on>
        <visualize>true</visualize>
        <update_rate>10</update_rate>
        <ray>
          <scan>
            <horizontal>
              <samples>360</samples>
              <resolution>1</resolution>
              <min_angle>0.0</min_angle>
              <max_angle>6.28318530718</max_angle>
            </horizontal>
          </scan>
          <range>
            <min>0.15</min>
            <max>12.0</max>
            <resolution>0.01</resolution>
          </range>
        </ray>
        <plugin name="scan" filename="libgazebo_ros_ray_sensor.so">
          <ros>
            <remapping>~/out:=scan</remapping>
          </ros>
          <output_type>sensor_msgs/LaserScan</output_type>
          <frame_name>laser_frame</frame_name>
        </plugin>
      </sensor>
    </link>

    <joint name="lidar_joint" type="fixed">
      <parent>base_link</parent>
      <child>laser_frame</child>
    </joint>

    <!-- Differential Drive Plugin -->
    <plugin name="diff_drive" filename="libgazebo_ros_diff_drive.so">
      <ros>
        <namespace>/</namespace>
      </ros>
      <left_joint>left_wheel_joint</left_joint>
      <right_joint>right_wheel_joint</right_joint>
      <wheel_separation>0.21</wheel_separation>
      <wheel_diameter>0.065</wheel_diameter>
      <max_wheel_torque>10</max_wheel_torque>
      <max_wheel_acceleration>1.0</max_wheel_acceleration>
      <publish_odom>true</publish_odom>
      <publish_odom_tf>true</publish_odom_tf>
      <publish_wheel_tf>true</publish_wheel_tf>
      <odometry_frame>odom</odometry_frame>
      <robot_base_frame>base_link</robot_base_frame>
    </plugin>
  </model>
</sdf>